Workbook

Sheet ENTRADA DATOS
A1: CONCURSO LORQUÍ
A2: INTRODUCIR PALOMO Y PUNTOS · FILAS 1 A 120
A3: Nº | B3: PALOMO | C3: PRUEBA 1 | D3: PRUEBA 2 | E3: PRUEBA 3 | F3: PRUEBA 4 | G3: PRUEBA 5 | H3: PRUEBA 6 | I3: TOTAL | J3: PLUMA | K3: PROPIETARIO
A4: 1 | I4: =IF(COUNTA(C4:H4)=0,"",SUM(C4:H4)) | L4: =IF(I4="","",I4*1000+(124-ROW()))
A5: 2 | I5: =IF(COUNTA(C5:H5)=0,"",SUM(C5:H5)) | L5: =IF(I5="","",I5*1000+(124-ROW()))
A6: 3 | I6: =IF(COUNTA(C6:H6)=0,"",SUM(C6:H6)) | L6: =IF(I6="","",I6*1000+(124-ROW()))
A7: 4 | I7: =IF(COUNTA(C7:H7)=0,"",SUM(C7:H7)) | L7: =IF(I7="","",I7*1000+(124-ROW()))
A8: 5 | I8: =IF(COUNTA(C8:H8)=0,"",SUM(C8:H8)) | L8: =IF(I8="","",I8*1000+(124-ROW()))
A9: 6 | I9: =IF(COUNTA(C9:H9)=0,"",SUM(C9:H9)) | L9: =IF(I9="","",I9*1000+(124-ROW()))
A10: 7 | I10: =IF(COUNTA(C10:H10)=0,"",SUM(C10:H10)) | L10: =IF(I10="","",I10*1000+(124-ROW()))
A11: 8 | I11: =IF(COUNTA(C11:H11)=0,"",SUM(C11:H11)) | L11: =IF(I11="","",I11*1000+(124-ROW()))
A12: 9 | I12: =IF(COUNTA(C12:H12)=0,"",SUM(C12:H12)) | L12: =IF(I12="","",I12*1000+(124-ROW()))
A13: 10 | I13: =IF(COUNTA(C13:H13)=0,"",SUM(C13:H13)) | L13: =IF(I13="","",I13*1000+(124-ROW()))
A14: 11 | I14: =IF(COUNTA(C14:H14)=0,"",SUM(C14:H14)) | L14: =IF(I14="","",I14*1000+(124-ROW()))
A15: 12 | I15: =IF(COUNTA(C15:H15)=0,"",SUM(C15:H15)) | L15: =IF(I15="","",I15*1000+(124-ROW()))
... A123: 120 | I123: =IF(COUNTA(C123:H123)=0,"",SUM(C123:H123)) | L123: =IF(I123="","",I123*1000+(124-ROW()))

Sheet CLASIFICACION
A1: CONCURSO LORQUÍ
A2: CLASIFICACIÓN AUTOMÁTICA · MAYOR TOTAL PRIMERO
A3: Nº | B3: PALOMO | C3: PRUEBA 1 | D3: PRUEBA 2 | E3: PRUEBA 3 | F3: PRUEBA 4 | G3: PRUEBA 5 | H3: PRUEBA 6 | I3: TOTAL | J3: PLUMA | K3: PROPIETARIO
A4: =IF(I4="","",1) | B4: =IFERROR(INDEX('ENTRADA DATOS'!$B$4:$B$123,MATCH(LARGE('ENTRADA DATOS'!$L$4:$L$123,1),'ENTRADA DATOS'!$L$4:$L$123,0)),"") | C4: =IFERROR(INDEX('ENTRADA DATOS'!$C$4:$C$123,MATCH(LARGE('ENTRADA DATOS'!$L$4:$L$123,1),'ENTRADA DATOS'!$L$4:$L$123,0)),"") | D4: =IFERROR(INDEX('ENTRADA DATOS'!$D$4:$D$123,MATCH(LARGE('ENTRADA DATOS'!$L$4:$L$123,1),'ENTRADA DATOS'!$L$4:$L$123,0)),"") | E4: =IFERROR(INDEX('ENTRADA DATOS'!$E$4:$E$123,MATCH(LARGE('ENTRADA DATOS'!$L$4:$L$123,1),'ENTRADA DATOS'!$L$4:$L$123,0)),"") | F4: =IFERROR(INDEX('ENTRADA DATOS'!$F$4:$F$123,MATCH(LARGE('ENTRADA DATOS'!$L$4:$L$123,1),'ENTRADA DATOS'!$L$4:$L$123,0)),"") | G4: =IFERROR(INDEX('ENTRADA DATOS'!$G$4:$G$123,MATCH(LARGE('ENTRADA DATOS'!$L$4:$L$123,1),'ENTRADA DATOS'!$L$4:$L$123,0)),"") | H4: =IFERROR(INDEX('ENTRADA DATOS'!$H$4:$H$123,MATCH(LARGE('ENTRADA DATOS'!$L$4:$L$123,1),'ENTRADA DATOS'!$L$4:$L$123,0)),"") | I4: =IFERROR(INDEX('ENTRADA DATOS'!$I$4:$I$123,MATCH(LARGE('ENTRADA DATOS'!$L$4:$L$123,1),'ENTRADA DATOS'!$L$4:$L$123,0)),"") | J4: =IFERROR(INDEX('ENTRADA DATOS'!$J$4:$J$123,MATCH(LARGE('ENTRADA DATOS'!$L$4:$L$123,1),'ENTRADA DATOS'!$L$4:$L$123,0)),"") | K4: =IFERROR(INDEX('ENTRADA DATOS'!$K$4:$K$123,MATCH(LARGE('ENTRADA DATOS'!$L$4:$L$123,1),'ENTRADA DATOS'!$L$4:$L$123,0)),"")
A5: =IF(I5="","",2) | B5: =IFERROR(INDEX('ENTRADA DATOS'!$B$4:$B$123,MATCH(LARGE('ENTRADA DATOS'!$L$4:$L$123,2),'ENTRADA DATOS'!$L$4:$L$123,0)),"") | C5: =IFERROR(INDEX('ENTRADA DATOS'!$C$4:$C$123,MATCH(LARGE('ENTRADA DATOS'!$L$4:$L$123,2),'ENTRADA DATOS'!$L$4:$L$123,0)),"") | D5: =IFERROR(INDEX('ENTRADA DATOS'!$D$4:$D$123,MATCH(LARGE('ENTRADA DATOS'!$L$4:$L$123,2),'ENTRADA DATOS'!$L$4:$L$123,0)),"") | E5: =IFERROR(INDEX('ENTRADA DATOS'!$E$4:$E$123,MATCH(LARGE('ENTRADA DATOS'!$L$4:$L$123,2),'ENTRADA DATOS'!$L$4:$L$123,0)),"") | F5: =IFERROR(INDEX('ENTRADA DATOS'!$F$4:$F$123,MATCH(LARGE('ENTRADA DATOS'!$L$4:$L$123,2),'ENTRADA DATOS'!$L$4:$L$123,0)),"") | G5: =IFERROR(INDEX('ENTRADA DATOS'!$G$4:$G$123,MATCH(LARGE('ENTRADA DATOS'!$L$4:$L$123,2),'ENTRADA DATOS'!$L$4:$L$123,0)),"") | H5: =IFERROR(INDEX('ENTRADA DATOS'!$H$4:$H$123,MATCH(LARGE('ENTRADA DATOS'!$L$4:$L$123,2),'ENTRADA DATOS'!$L$4:$L$123,0)),"") | I5: =IFERROR(INDEX('ENTRADA DATOS'!$I$4:$I$123,MATCH(LARGE('ENTRADA DATOS'!$L$4:$L$123,2),'ENTRADA DATOS'!$L$4:$L$123,0)),"") | J5: =IFERROR(INDEX('ENTRADA DATOS'!$J$4:$J$123,MATCH(LARGE('ENTRADA DATOS'!$L$4:$L$123,2),'ENTRADA DATOS'!$L$4:$L$123,0)),"") | K5: =IFERROR(INDEX('ENTRADA DATOS'!$K$4:$K$123,MATCH(LARGE('ENTRADA DATOS'!$L$4:$L$123,2),'ENTRADA DATOS'!$L$4:$L$123,0)),"")
A6: =IF(I6="","",3) | B6: =IFERROR(INDEX('ENTRADA DATOS'!$B$4:$B$123,MATCH(LARGE('ENTRADA DATOS'!$L$4:$L$123,3),'ENTRADA DATOS'!$L$4:$L$123,0)),"") | C6: =IFERROR(INDEX('ENTRADA DATOS'!$C$4:$C$123,MATCH(LARGE('ENTRADA DATOS'!$L$4:$L$123,3),'ENTRADA DATOS'!$L$4:$L$123,0)),"") | D6: =IFERROR(INDEX('ENTRADA DATOS'!$D$4:$D$123,MATCH(LARGE('ENTRADA DATOS'!$L$4:$L$123,3),'ENTRADA DATOS'!$L$4:$L$123,0)),"") | E6: =IFERROR(INDEX('ENTRADA DATOS'!$E$4:$E$123,MATCH(LARGE('ENTRADA DATOS'!$L$4:$L$123,3),'ENTRADA DATOS'!$L$4:$L$123,0)),"") | F6: =IFERROR(INDEX('ENTRADA DATOS'!$F$4:$F$123,MATCH(LARGE('ENTRADA DATOS'!$L$4:$L$123,3),'ENTRADA DATOS'!$L$4:$L$123,0)),"") | G6: =IFERROR(INDEX('ENTRADA DATOS'!$G$4:$G$123,MATCH(LARGE('ENTRADA DATOS'!$L$4:$L$123,3),'ENTRADA DATOS'!$L$4:$L$123,0)),"") | H6: =IFERROR(INDEX('ENTRADA DATOS'!$H$4:$H$123,MATCH(LARGE('ENTRADA DATOS'!$L$4:$L$123,3),'ENTRADA DATOS'!$L$4:$L$123,0)),"") | I6: =IFERROR(INDEX('ENTRADA DATOS'!$I$4:$I$123,MATCH(LARGE('ENTRADA DATOS'!$L$4:$L$123,3),'ENTRADA DATOS'!$L$4:$L$123,0)),"") | J6: =IFERROR(INDEX('ENTRADA DATOS'!$J$4:$J$123,MATCH(LARGE('ENTRADA DATOS'!$L$4:$L$123,3),'ENTRADA DATOS'!$L$4:$L$123,0)),"") | K6: =IFERROR(INDEX('ENTRADA DATOS'!$K$4:$K$123,MATCH(LARGE('ENTRADA DATOS'!$L$4:$L$123,3),'ENTRADA DATOS'!$L$4:$L$123,0)),"")
A7: =IF(I7="","",4) | B7: =IFERROR(INDEX('ENTRADA DATOS'!$B$4:$B$123,MATCH(LARGE('ENTRADA DATOS'!$L$4:$L$123,4),'ENTRADA DATOS'!$L$4:$L$123,0)),"") | C7: =IFERROR(INDEX('ENTRADA DATOS'!$C$4:$C$123,MATCH(LARGE('ENTRADA DATOS'!$L$4:$L$123,4),'ENTRADA DATOS'!$L$4:$L$123,0)),"") | D7: =IFERROR(INDEX('ENTRADA DATOS'!$D$4:$D$123,MATCH(LARGE('ENTRADA DATOS'!$L$4:$L$123,4),'ENTRADA DATOS'!$L$4:$L$123,0)),"") | E7: =IFERROR(INDEX('ENTRADA DATOS'!$E$4:$E$123,MATCH(LARGE('ENTRADA DATOS'!$L$4:$L$123,4),'ENTRADA DATOS'!$L$4:$L$123,0)),"") | F7: =IFERROR(INDEX('ENTRADA DATOS'!$F$4:$F$123,MATCH(LARGE('ENTRADA DATOS'!$L$4:$L$123,4),'ENTRADA DATOS'!$L$4:$L$123,0)),"") | G7: =IFERROR(INDEX('ENTRADA DATOS'!$G$4:$G$123,MATCH(LARGE('ENTRADA DATOS'!$L$4:$L$123,4),'ENTRADA DATOS'!$L$4:$L$123,0)),"") | H7: =IFERROR(INDEX('ENTRADA DATOS'!$H$4:$H$123,MATCH(LARGE('ENTRADA DATOS'!$L$4:$L$123,4),'ENTRADA DATOS'!$L$4:$L$123,0)),"") | I7: =IFERROR(INDEX('ENTRADA DATOS'!$I$4:$I$123,MATCH(LARGE('ENTRADA DATOS'!$L$4:$L$123,4),'ENTRADA DATOS'!$L$4:$L$123,0)),"") | J7: =IFERROR(INDEX('ENTRADA DATOS'!$J$4:$J$123,MATCH(LARGE('ENTRADA DATOS'!$L$4:$L$123,4),'ENTRADA DATOS'!$L$4:$L$123,0)),"") | K7: =IFERROR(INDEX('ENTRADA DATOS'!$K$4:$K$123,MATCH(LARGE('ENTRADA DATOS'!$L$4:$L$123,4),'ENTRADA DATOS'!$L$4:$L$123,0)),"")
A8: =IF(I8="","",5) | B8: =IFERROR(INDEX('ENTRADA DATOS'!$B$4:$B$123,MATCH(LARGE('ENTRADA DATOS'!$L$4:$L$123,5),'ENTRADA DATOS'!$L$4:$L$123,0)),"") | C8: =IFERROR(INDEX('ENTRADA DATOS'!$C$4:$C$123,MATCH(LARGE('ENTRADA DATOS'!$L$4:$L$123,5),'ENTRADA DATOS'!$L$4:$L$123,0)),"") | D8: =IFERROR(INDEX('ENTRADA DATOS'!$D$4:$D$123,MATCH(LARGE('ENTRADA DATOS'!$L$4:$L$123,5),'ENTRADA DATOS'!$L$4:$L$123,0)),"") | E8: =IFERROR(INDEX('ENTRADA DATOS'!$E$4:$E$123,MATCH(LARGE('ENTRADA DATOS'!$L$4:$L$123,5),'ENTRADA DATOS'!$L$4:$L$123,0)),"") | F8: =IFERROR(INDEX('ENTRADA DATOS'!$F$4:$F$123,MATCH(LARGE('ENTRADA DATOS'!$L$4:$L$123,5),'ENTRADA DATOS'!$L$4:$L$123,0)),"") | G8: =IFERROR(INDEX('ENTRADA DATOS'!$G$4:$G$123,MATCH(LARGE('ENTRADA DATOS'!$L$4:$L$123,5),'ENTRADA DATOS'!$L$4:$L$123,0)),"") | H8: =IFERROR(INDEX('ENTRADA DATOS'!$H$4:$H$123,MATCH(LARGE('ENTRADA DATOS'!$L$4:$L$123,5),'ENTRADA DATOS'!$L$4:$L$123,0)),"") | I8: =IFERROR(INDEX('ENTRADA DATOS'!$I$4:$I$123,MATCH(LARGE('ENTRADA DATOS'!$L$4:$L$123,5),'ENTRADA DATOS'!$L$4:$L$123,0)),"") | J8: =IFERROR(INDEX('ENTRADA DATOS'!$J$4:$J$123,MATCH(LARGE('ENTRADA DATOS'!$L$4:$L$123,5),'ENTRADA DATOS'!$L$4:$L$123,0)),"") | K8: =IFERROR(INDEX('ENTRADA DATOS'!$K$4:$K$123,MATCH(LARGE('ENTRADA DATOS'!$L$4:$L$123,5),'ENTRADA DATOS'!$L$4:$L$123,0)),"")
A9: =IF(I9="","",6) | B9: =IFERROR(INDEX('ENTRADA DATOS'!$B$4:$B$123,MATCH(LARGE('ENTRADA DATOS'!$L$4:$L$123,6),'ENTRADA DATOS'!$L$4:$L$123,0)),"") | C9: =IFERROR(INDEX('ENTRADA DATOS'!$C$4:$C$123,MATCH(LARGE('ENTRADA DATOS'!$L$4:$L$123,6),'ENTRADA DATOS'!$L$4:$L$123,0)),"") | D9: =IFERROR(INDEX('ENTRADA DATOS'!$D$4:$D$123,MATCH(LARGE('ENTRADA DATOS'!$L$4:$L$123,6),'ENTRADA DATOS'!$L$4:$L$123,0)),"") | E9: =IFERROR(INDEX('ENTRADA DATOS'!$E$4:$E$123,MATCH(LARGE('ENTRADA DATOS'!$L$4:$L$123,6),'ENTRADA DATOS'!$L$4:$L$123,0)),"") | F9: =IFERROR(INDEX('ENTRADA DATOS'!$F$4:$F$123,MATCH(LARGE('ENTRADA DATOS'!$L$4:$L$123,6),'ENTRADA DATOS'!$L$4:$L$123,0)),"") | G9: =IFERROR(INDEX('ENTRADA DATOS'!$G$4:$G$123,MATCH(LARGE('ENTRADA DATOS'!$L$4:$L$123,6),'ENTRADA DATOS'!$L$4:$L$123,0)),"") | H9: =IFERROR(INDEX('ENTRADA DATOS'!$H$4:$H$123,MATCH(LARGE('ENTRADA DATOS'!$L$4:$L$123,6),'ENTRADA DATOS'!$L$4:$L$123,0)),"") | I9: =IFERROR(INDEX('ENTRADA DATOS'!$I$4:$I$123,MATCH(LARGE('ENTRADA DATOS'!$L$4:$L$123,6),'ENTRADA DATOS'!$L$4:$L$123,0)),"") | J9: =IFERROR(INDEX('ENTRADA DATOS'!$J$4:$J$123,MATCH(LARGE('ENTRADA DATOS'!$L$4:$L$123,6),'ENTRADA DATOS'!$L$4:$L$123,0)),"") | K9: =IFERROR(INDEX('ENTRADA DATOS'!$K$4:$K$123,MATCH(LARGE('ENTRADA DATOS'!$L$4:$L$123,6),'ENTRADA DATOS'!$L$4:$L$123,0)),"")
A10: =IF(I10="","",7) | B10: =IFERROR(INDEX('ENTRADA DATOS'!$B$4:$B$123,MATCH(LARGE('ENTRADA DATOS'!$L$4:$L$123,7),'ENTRADA DATOS'!$L$4:$L$123,0)),"") | C10: =IFERROR(INDEX('ENTRADA DATOS'!$C$4:$C$123,MATCH(LARGE('ENTRADA DATOS'!$L$4:$L$123,7),'ENTRADA DATOS'!$L$4:$L$123,0)),"") | D10: =IFERROR(INDEX('ENTRADA DATOS'!$D$4:$D$123,MATCH(LARGE('ENTRADA DATOS'!$L$4:$L$123,7),'ENTRADA DATOS'!$L$4:$L$123,0)),"") | E10: =IFERROR(INDEX('ENTRADA DATOS'!$E$4:$E$123,MATCH(LARGE('ENTRADA DATOS'!$L$4:$L$123,7),'ENTRADA DATOS'!$L$4:$L$123,0)),"") | F10: =IFERROR(INDEX('ENTRADA DATOS'!$F$4:$F$123,MATCH(LARGE('ENTRADA DATOS'!$L$4:$L$123,7),'ENTRADA DATOS'!$L$4:$L$123,0)),"") | G10: =IFERROR(INDEX('ENTRADA DATOS'!$G$4:$G$123,MATCH(LARGE('ENTRADA DATOS'!$L$4:$L$123,7),'ENTRADA DATOS'!$L$4:$L$123,0)),"") | H10: =IFERROR(INDEX('ENTRADA DATOS'!$H$4:$H$123,MATCH(LARGE('ENTRADA DATOS'!$L$4:$L$123,7),'ENTRADA DATOS'!$L$4:$L$123,0)),"") | I10: =IFERROR(INDEX('ENTRADA DATOS'!$I$4:$I$123,MATCH(LARGE('ENTRADA DATOS'!$L$4:$L$123,7),'ENTRADA DATOS'!$L$4:$L$123,0)),"") | J10: =IFERROR(INDEX('ENTRADA DATOS'!$J$4:$J$123,MATCH(LARGE('ENTRADA DATOS'!$L$4:$L$123,7),'ENTRADA DATOS'!$L$4:$L$123,0)),"") | K10: =IFERROR(INDEX('ENTRADA DATOS'!$K$4:$K$123,MATCH(LARGE('ENTRADA DATOS'!$L$4:$L$123,7),'ENTRADA DATOS'!$L$4:$L$123,0)),"")
A11: =IF(I11="","",8) | B11: =IFERROR(INDEX('ENTRADA DATOS'!$B$4:$B$123,MATCH(LARGE('ENTRADA DATOS'!$L$4:$L$123,8),'ENTRADA DATOS'!$L$4:$L$123,0)),"") | C11: =IFERROR(INDEX('ENTRADA DATOS'!$C$4:$C$123,MATCH(LARGE('ENTRADA DATOS'!$L$4:$L$123,8),'ENTRADA DATOS'!$L$4:$L$123,0)),"") | D11: =IFERROR(INDEX('ENTRADA DATOS'!$D$4:$D$123,MATCH(LARGE('ENTRADA DATOS'!$L$4:$L$123,8),'ENTRADA DATOS'!$L$4:$L$123,0)),"") | E11: =IFERROR(INDEX('ENTRADA DATOS'!$E$4:$E$123,MATCH(LARGE('ENTRADA DATOS'!$L$4:$L$123,8),'ENTRADA DATOS'!$L$4:$L$123,0)),"") | F11: =IFERROR(INDEX('ENTRADA DATOS'!$F$4:$F$123,MATCH(LARGE('ENTRADA DATOS'!$L$4:$L$123,8),'ENTRADA DATOS'!$L$4:$L$123,0)),"") | G11: =IFERROR(INDEX('ENTRADA DATOS'!$G$4:$G$123,MATCH(LARGE('ENTRADA DATOS'!$L$4:$L$123,8),'ENTRADA DATOS'!$L$4:$L$123,0)),"") | H11: =IFERROR(INDEX('ENTRADA DATOS'!$H$4:$H$123,MATCH(LARGE('ENTRADA DATOS'!$L$4:$L$123,8),'ENTRADA DATOS'!$L$4:$L$123,0)),"") | I11: =IFERROR(INDEX('ENTRADA DATOS'!$I$4:$I$123,MATCH(LARGE('ENTRADA DATOS'!$L$4:$L$123,8),'ENTRADA DATOS'!$L$4:$L$123,0)),"") | J11: =IFERROR(INDEX('ENTRADA DATOS'!$J$4:$J$123,MATCH(LARGE('ENTRADA DATOS'!$L$4:$L$123,8),'ENTRADA DATOS'!$L$4:$L$123,0)),"") | K11: =IFERROR(INDEX('ENTRADA DATOS'!$K$4:$K$123,MATCH(LARGE('ENTRADA DATOS'!$L$4:$L$123,8),'ENTRADA DATOS'!$L$4:$L$123,0)),"")
A12: =IF(I12="","",9) | B12: =IFERROR(INDEX('ENTRADA DATOS'!$B$4:$B$123,MATCH(LARGE('ENTRADA DATOS'!$L$4:$L$123,9),'ENTRADA DATOS'!$L$4:$L$123,0)),"") | C12: =IFERROR(INDEX('ENTRADA DATOS'!$C$4:$C$123,MATCH(LARGE('ENTRADA DATOS'!$L$4:$L$123,9),'ENTRADA DATOS'!$L$4:$L$123,0)),"") | D12: =IFERROR(INDEX('ENTRADA DATOS'!$D$4:$D$123,MATCH(LARGE('ENTRADA DATOS'!$L$4:$L$123,9),'ENTRADA DATOS'!$L$4:$L$123,0)),"") | E12: =IFERROR(INDEX('ENTRADA DATOS'!$E$4:$E$123,MATCH(LARGE('ENTRADA DATOS'!$L$4:$L$123,9),'ENTRADA DATOS'!$L$4:$L$123,0)),"") | F12: =IFERROR(INDEX('ENTRADA DATOS'!$F$4:$F$123,MATCH(LARGE('ENTRADA DATOS'!$L$4:$L$123,9),'ENTRADA DATOS'!$L$4:$L$123,0)),"") | G12: =IFERROR(INDEX('ENTRADA DATOS'!$G$4:$G$123,MATCH(LARGE('ENTRADA DATOS'!$L$4:$L$123,9),'ENTRADA DATOS'!$L$4:$L$123,0)),"") | H12: =IFERROR(INDEX('ENTRADA DATOS'!$H$4:$H$123,MATCH(LARGE('ENTRADA DATOS'!$L$4:$L$123,9),'ENTRADA DATOS'!$L$4:$L$123,0)),"") | I12: =IFERROR(INDEX('ENTRADA DATOS'!$I$4:$I$123,MATCH(LARGE('ENTRADA DATOS'!$L$4:$L$123,9),'ENTRADA DATOS'!$L$4:$L$123,0)),"") | J12: =IFERROR(INDEX('ENTRADA DATOS'!$J$4:$J$123,MATCH(LARGE('ENTRADA DATOS'!$L$4:$L$123,9),'ENTRADA DATOS'!$L$4:$L$123,0)),"") | K12: =IFERROR(INDEX('ENTRADA DATOS'!$K$4:$K$123,MATCH(LARGE('ENTRADA DATOS'!$L$4:$L$123,9),'ENTRADA DATOS'!$L$4:$L$123,0)),"")
A13: =IF(I13="","",10) | B13: =IFERROR(INDEX('ENTRADA DATOS'!$B$4:$B$123,MATCH(LARGE('ENTRADA DATOS'!$L$4:$L$123,10),'ENTRADA DATOS'!$L$4:$L$123,0)),"") | C13: =IFERROR(INDEX('ENTRADA DATOS'!$C$4:$C$123,MATCH(LARGE('ENTRADA DATOS'!$L$4:$L$123,10),'ENTRADA DATOS'!$L$4:$L$123,0)),"") | D13: =IFERROR(INDEX('ENTRADA DATOS'!$D$4:$D$123,MATCH(LARGE('ENTRADA DATOS'!$L$4:$L$123,10),'ENTRADA DATOS'!$L$4:$L$123,0)),"") | E13: =IFERROR(INDEX('ENTRADA DATOS'!$E$4:$E$123,MATCH(LARGE('ENTRADA DATOS'!$L$4:$L$123,10),'ENTRADA DATOS'!$L$4:$L$123,0)),"") | F13: =IFERROR(INDEX('ENTRADA DATOS'!$F$4:$F$123,MATCH(LARGE('ENTRADA DATOS'!$L$4:$L$123,10),'ENTRADA DATOS'!$L$4:$L$123,0)),"") | G13: =IFERROR(INDEX('ENTRADA DATOS'!$G$4:$G$123,MATCH(LARGE('ENTRADA DATOS'!$L$4:$L$123,10),'ENTRADA DATOS'!$L$4:$L$123,0)),"") | H13: =IFERROR(INDEX('ENTRADA DATOS'!$H$4:$H$123,MATCH(LARGE('ENTRADA DATOS'!$L$4:$L$123,10),'ENTRADA DATOS'!$L$4:$L$123,0)),"") | I13: =IFERROR(INDEX('ENTRADA DATOS'!$I$4:$I$123,MATCH(LARGE('ENTRADA DATOS'!$L$4:$L$123,10),'ENTRADA DATOS'!$L$4:$L$123,0)),"") | J13: =IFERROR(INDEX('ENTRADA DATOS'!$J$4:$J$123,MATCH(LARGE('ENTRADA DATOS'!$L$4:$L$123,10),'ENTRADA DATOS'!$L$4:$L$123,0)),"") | K13: =IFERROR(INDEX('ENTRADA DATOS'!$K$4:$K$123,MATCH(LARGE('ENTRADA DATOS'!$L$4:$L$123,10),'ENTRADA DATOS'!$L$4:$L$123,0)),"")
A14: =IF(I14="","",11) | B14: =IFERROR(INDEX('ENTRADA DATOS'!$B$4:$B$123,MATCH(LARGE('ENTRADA DATOS'!$L$4:$L$123,11),'ENTRADA DATOS'!$L$4:$L$123,0)),"") | C14: =IFERROR(INDEX('ENTRADA DATOS'!$C$4:$C$123,MATCH(LARGE('ENTRADA DATOS'!$L$4:$L$123,11),'ENTRADA DATOS'!$L$4:$L$123,0)),"") | D14: =IFERROR(INDEX('ENTRADA DATOS'!$D$4:$D$123,MATCH(LARGE('ENTRADA DATOS'!$L$4:$L$123,11),'ENTRADA DATOS'!$L$4:$L$123,0)),"") | E14: =IFERROR(INDEX('ENTRADA DATOS'!$E$4:$E$123,MATCH(LARGE('ENTRADA DATOS'!$L$4:$L$123,11),'ENTRADA DATOS'!$L$4:$L$123,0)),"") | F14: =IFERROR(INDEX('ENTRADA DATOS'!$F$4:$F$123,MATCH(LARGE('ENTRADA DATOS'!$L$4:$L$123,11),'ENTRADA DATOS'!$L$4:$L$123,0)),"") | G14: =IFERROR(INDEX('ENTRADA DATOS'!$G$4:$G$123,MATCH(LARGE('ENTRADA DATOS'!$L$4:$L$123,11),'ENTRADA DATOS'!$L$4:$L$123,0)),"") | H14: =IFERROR(INDEX('ENTRADA DATOS'!$H$4:$H$123,MATCH(LARGE('ENTRADA DATOS'!$L$4:$L$123,11),'ENTRADA DATOS'!$L$4:$L$123,0)),"") | I14: =IFERROR(INDEX('ENTRADA DATOS'!$I$4:$I$123,MATCH(LARGE('ENTRADA DATOS'!$L$4:$L$123,11),'ENTRADA DATOS'!$L$4:$L$123,0)),"") | J14: =IFERROR(INDEX('ENTRADA DATOS'!$J$4:$J$123,MATCH(LARGE('ENTRADA DATOS'!$L$4:$L$123,11),'ENTRADA DATOS'!$L$4:$L$123,0)),"") | K14: =IFERROR(INDEX('ENTRADA DATOS'!$K$4:$K$123,MATCH(LARGE('ENTRADA DATOS'!$L$4:$L$123,11),'ENTRADA DATOS'!$L$4:$L$123,0)),"")
A15: =IF(I15="","",12) | B15: =IFERROR(INDEX('ENTRADA DATOS'!$B$4:$B$123,MATCH(LARGE('ENTRADA DATOS'!$L$4:$L$123,12),'ENTRADA DATOS'!$L$4:$L$123,0)),"") | C15: =IFERROR(INDEX('ENTRADA DATOS'!$C$4:$C$123,MATCH(LARGE('ENTRADA DATOS'!$L$4:$L$123,12),'ENTRADA DATOS'!$L$4:$L$123,0)),"") | D15: =IFERROR(INDEX('ENTRADA DATOS'!$D$4:$D$123,MATCH(LARGE('ENTRADA DATOS'!$L$4:$L$123,12),'ENTRADA DATOS'!$L$4:$L$123,0)),"") | E15: =IFERROR(INDEX('ENTRADA DATOS'!$E$4:$E$123,MATCH(LARGE('ENTRADA DATOS'!$L$4:$L$123,12),'ENTRADA DATOS'!$L$4:$L$123,0)),"") | F15: =IFERROR(INDEX('ENTRADA DATOS'!$F$4:$F$123,MATCH(LARGE('ENTRADA DATOS'!$L$4:$L$123,12),'ENTRADA DATOS'!$L$4:$L$123,0)),"") | G15: =IFERROR(INDEX('ENTRADA DATOS'!$G$4:$G$123,MATCH(LARGE('ENTRADA DATOS'!$L$4:$L$123,12),'ENTRADA DATOS'!$L$4:$L$123,0)),"") | H15: =IFERROR(INDEX('ENTRADA DATOS'!$H$4:$H$123,MATCH(LARGE('ENTRADA DATOS'!$L$4:$L$123,12),'ENTRADA DATOS'!$L$4:$L$123,0)),"") | I15: =IFERROR(INDEX('ENTRADA DATOS'!$I$4:$I$123,MATCH(LARGE('ENTRADA DATOS'!$L$4:$L$123,12),'ENTRADA DATOS'!$L$4:$L$123,0)),"") | J15: =IFERROR(INDEX('ENTRADA DATOS'!$J$4:$J$123,MATCH(LARGE('ENTRADA DATOS'!$L$4:$L$123,12),'ENTRADA DATOS'!$L$4:$L$123,0)),"") | K15: =IFERROR(INDEX('ENTRADA DATOS'!$K$4:$K$123,MATCH(LARGE('ENTRADA DATOS'!$L$4:$L$123,12),'ENTRADA DATOS'!$L$4:$L$123,0)),"")
A16: =IF(I16="","",13) | B16: =IFERROR(INDEX('ENTRADA DATOS'!$B$4:$B$123,MATCH(LARGE('ENTRADA DATOS'!$L$4:$L$123,13),'ENTRADA DATOS'!$L$4:$L$123,0)),"") | C16: =IFERROR(INDEX('ENTRADA DATOS'!$C$4:$C$123,MATCH(LARGE('ENTRADA DATOS'!$L$4:$L$123,13),'ENTRADA DATOS'!$L$4:$L$123,0)),"") | D16: =IFERROR(INDEX('ENTRADA DATOS'!$D$4:$D$123,MATCH(LARGE('ENTRADA DATOS'!$L$4:$L$123,13),'ENTRADA DATOS'!$L$4:$L$123,0)),"") | E16: =IFERROR(INDEX('ENTRADA DATOS'!$E$4:$E$123,MATCH(LARGE('ENTRADA DATOS'!$L$4:$L$123,13),'ENTRADA DATOS'!$L$4:$L$123,0)),"") | F16: =IFERROR(INDEX('ENTRADA DATOS'!$F$4:$F$123,MATCH(LARGE('ENTRADA DATOS'!$L$4:$L$123,13),'ENTRADA DATOS'!$L$4:$L$123,0)),"") | G16: =IFERROR(INDEX('ENTRADA DATOS'!$G$4:$G$123,MATCH(LARGE('ENTRADA DATOS'!$L$4:$L$123,13),'ENTRADA DATOS'!$L$4:$L$123,0)),"") | H16: =IFERROR(INDEX('ENTRADA DATOS'!$H$4:$H$123,MATCH(LARGE('ENTRADA DATOS'!$L$4:$L$123,13),'ENTRADA DATOS'!$L$4:$L$123,0)),"") | I16: =IFERROR(INDEX('ENTRADA DATOS'!$I$4:$I$123,MATCH(LARGE('ENTRADA DATOS'!$L$4:$L$123,13),'ENTRADA DATOS'!$L$4:$L$123,0)),"") | J16: =IFERROR(INDEX('ENTRADA DATOS'!$J$4:$J$123,MATCH(LARGE('ENTRADA DATOS'!$L$4:$L$123,13),'ENTRADA DATOS'!$L$4:$L$123,0)),"") | K16: =IFERROR(INDEX('ENTRADA DATOS'!$K$4:$K$123,MATCH(LARGE('ENTRADA DATOS'!$L$4:$L$123,13),'ENTRADA DATOS'!$L$4:$L$123,0)),"")
A17: =IF(I17="","",14) | B17: =IFERROR(INDEX('ENTRADA DATOS'!$B$4:$B$123,MATCH(LARGE('ENTRADA DATOS'!$L$4:$L$123,14),'ENTRADA DATOS'!$L$4:$L$123,0)),"") | C17: =IFERROR(INDEX('ENTRADA DATOS'!$C$4:$C$123,MATCH(LARGE('ENTRADA DATOS'!$L$4:$L$123,14),'ENTRADA DATOS'!$L$4:$L$123,0)),"") | D17: =IFERROR(INDEX('ENTRADA DATOS'!$D$4:$D$123,MATCH(LARGE('ENTRADA DATOS'!$L$4:$L$123,14),'ENTRADA DATOS'!$L$4:$L$123,0)),"") | E17: =IFERROR(INDEX('ENTRADA DATOS'!$E$4:$E$123,MATCH(LARGE('ENTRADA DATOS'!$L$4:$L$123,14),'ENTRADA DATOS'!$L$4:$L$123,0)),"") | F17: =IFERROR(INDEX('ENTRADA DATOS'!$F$4:$F$123,MATCH(LARGE('ENTRADA DATOS'!$L$4:$L$123,14),'ENTRADA DATOS'!$L$4:$L$123,0)),"") | G17: =IFERROR(INDEX('ENTRADA DATOS'!$G$4:$G$123,MATCH(LARGE('ENTRADA DATOS'!$L$4:$L$123,14),'ENTRADA DATOS'!$L$4:$L$123,0)),"") | H17: =IFERROR(INDEX('ENTRADA DATOS'!$H$4:$H$123,MATCH(LARGE('ENTRADA DATOS'!$L$4:$L$123,14),'ENTRADA DATOS'!$L$4:$L$123,0)),"") | I17: =IFERROR(INDEX('ENTRADA DATOS'!$I$4:$I$123,MATCH(LARGE('ENTRADA DATOS'!$L$4:$L$123,14),'ENTRADA DATOS'!$L$4:$L$123,0)),"") | J17: =IFERROR(INDEX('ENTRADA DATOS'!$J$4:$J$123,MATCH(LARGE('ENTRADA DATOS'!$L$4:$L$123,14),'ENTRADA DATOS'!$L$4:$L$123,0)),"") | K17: =IFERROR(INDEX('ENTRADA DATOS'!$K$4:$K$123,MATCH(LARGE('ENTRADA DATOS'!$L$4:$L$123,14),'ENTRADA DATOS'!$L$4:$L$123,0)),"")
A18: =IF(I18="","",15) | B18: =IFERROR(INDEX('ENTRADA DATOS'!$B$4:$B$123,MATCH(LARGE('ENTRADA DATOS'!$L$4:$L$123,15),'ENTRADA DATOS'!$L$4:$L$123,0)),"") | C18: =IFERROR(INDEX('ENTRADA DATOS'!$C$4:$C$123,MATCH(LARGE('ENTRADA DATOS'!$L$4:$L$123,15),'ENTRADA DATOS'!$L$4:$L$123,0)),"") | D18: =IFERROR(INDEX('ENTRADA DATOS'!$D$4:$D$123,MATCH(LARGE('ENTRADA DATOS'!$L$4:$L$123,15),'ENTRADA DATOS'!$L$4:$L$123,0)),"") | E18: =IFERROR(INDEX('ENTRADA DATOS'!$E$4:$E$123,MATCH(LARGE('ENTRADA DATOS'!$L$4:$L$123,15),'ENTRADA DATOS'!$L$4:$L$123,0)),"") | F18: =IFERROR(INDEX('ENTRADA DATOS'!$F$4:$F$123,MATCH(LARGE('ENTRADA DATOS'!$L$4:$L$123,15),'ENTRADA DATOS'!$L$4:$L$123,0)),"") | G18: =IFERROR(INDEX('ENTRADA DATOS'!$G$4:$G$123,MATCH(LARGE('ENTRADA DATOS'!$L$4:$L$123,15),'ENTRADA DATOS'!$L$4:$L$123,0)),"") | H18: =IFERROR(INDEX('ENTRADA DATOS'!$H$4:$H$123,MATCH(LARGE('ENTRADA DATOS'!$L$4:$L$123,15),'ENTRADA DATOS'!$L$4:$L$123,0)),"") | I18: =IFERROR(INDEX('ENTRADA DATOS'!$I$4:$I$123,MATCH(LARGE('ENTRADA DATOS'!$L$4:$L$123,15),'ENTRADA DATOS'!$L$4:$L$123,0)),"") | J18: =IFERROR(INDEX('ENTRADA DATOS'!$J$4:$J$123,MATCH(LARGE('ENTRADA DATOS'!$L$4:$L$123,15),'ENTRADA DATOS'!$L$4:$L$123,0)),"") | K18: =IFERROR(INDEX('ENTRADA DATOS'!$K$4:$K$123,MATCH(LARGE('ENTRADA DATOS'!$L$4:$L$123,15),'ENTRADA DATOS'!$L$4:$L$123,0)),"")
A19: =IF(I19="","",16) | B19: =IFERROR(INDEX('ENTRADA DATOS'!$B$4:$B$123,MATCH(LARGE('ENTRADA DATOS'!$L$4:$L$123,16),'ENTRADA DATOS'!$L$4:$L$123,0)),"") | C19: =IFERROR(INDEX('ENTRADA DATOS'!$C$4:$C$123,MATCH(LARGE('ENTRADA DATOS'!$L$4:$L$123,16),'ENTRADA DATOS'!$L$4:$L$123,0)),"") | D19: =IFERROR(INDEX('ENTRADA DATOS'!$D$4:$D$123,MATCH(LARGE('ENTRADA DATOS'!$L$4:$L$123,16),'ENTRADA DATOS'!$L$4:$L$123,0)),"") | E19: =IFERROR(INDEX('ENTRADA DATOS'!$E$4:$E$123,MATCH(LARGE('ENTRADA DATOS'!$L$4:$L$123,16),'ENTRADA DATOS'!$L$4:$L$123,0)),"") | F19: =IFERROR(INDEX('ENTRADA DATOS'!$F$4:$F$123,MATCH(LARGE('ENTRADA DATOS'!$L$4:$L$123,16),'ENTRADA DATOS'!$L$4:$L$123,0)),"") | G19: =IFERROR(INDEX('ENTRADA DATOS'!$G$4:$G$123,MATCH(LARGE('ENTRADA DATOS'!$L$4:$L$123,16),'ENTRADA DATOS'!$L$4:$L$123,0)),"") | H19: =IFERROR(INDEX('ENTRADA DATOS'!$H$4:$H$123,MATCH(LARGE('ENTRADA DATOS'!$L$4:$L$123,16),'ENTRADA DATOS'!$L$4:$L$123,0)),"") | I19: =IFERROR(INDEX('ENTRADA DATOS'!$I$4:$I$123,MATCH(LARGE('ENTRADA DATOS'!$L$4:$L$123,16),'ENTRADA DATOS'!$L$4:$L$123,0)),"") | J19: =IFERROR(INDEX('ENTRADA DATOS'!$J$4:$J$123,MATCH(LARGE('ENTRADA DATOS'!$L$4:$L$123,16),'ENTRADA DATOS'!$L$4:$L$123,0)),"") | K19: =IFERROR(INDEX('ENTRADA DATOS'!$K$4:$K$123,MATCH(LARGE('ENTRADA DATOS'!$L$4:$L$123,16),'ENTRADA DATOS'!$L$4:$L$123,0)),"")
A20: =IF(I20="","",17) | B20: =IFERROR(INDEX('ENTRADA DATOS'!$B$4:$B$123,MATCH(LARGE('ENTRADA DATOS'!$L$4:$L$123,17),'ENTRADA DATOS'!$L$4:$L$123,0)),"") | C20: =IFERROR(INDEX('ENTRADA DATOS'!$C$4:$C$123,MATCH(LARGE('ENTRADA DATOS'!$L$4:$L$123,17),'ENTRADA DATOS'!$L$4:$L$123,0)),"") | D20: =IFERROR(INDEX('ENTRADA DATOS'!$D$4:$D$123,MATCH(LARGE('ENTRADA DATOS'!$L$4:$L$123,17),'ENTRADA DATOS'!$L$4:$L$123,0)),"") | E20: =IFERROR(INDEX('ENTRADA DATOS'!$E$4:$E$123,MATCH(LARGE('ENTRADA DATOS'!$L$4:$L$123,17),'ENTRADA DATOS'!$L$4:$L$123,0)),"") | F20: =IFERROR(INDEX('ENTRADA DATOS'!$F$4:$F$123,MATCH(LARGE('ENTRADA DATOS'!$L$4:$L$123,17),'ENTRADA DATOS'!$L$4:$L$123,0)),"") | G20: =IFERROR(INDEX('ENTRADA DATOS'!$G$4:$G$123,MATCH(LARGE('ENTRADA DATOS'!$L$4:$L$123,17),'ENTRADA DATOS'!$L$4:$L$123,0)),"") | H20: =IFERROR(INDEX('ENTRADA DATOS'!$H$4:$H$123,MATCH(LARGE('ENTRADA DATOS'!$L$4:$L$123,17),'ENTRADA DATOS'!$L$4:$L$123,0)),"") | I20: =IFERROR(INDEX('ENTRADA DATOS'!$I$4:$I$123,MATCH(LARGE('ENTRADA DATOS'!$L$4:$L$123,17),'ENTRADA DATOS'!$L$4:$L$123,0)),"") | J20: =IFERROR(INDEX('ENTRADA DATOS'!$J$4:$J$123,MATCH(LARGE('ENTRADA DATOS'!$L$4:$L$123,17),'ENTRADA DATOS'!$L$4:$L$123,0)),"") | K20: =IFERROR(INDEX('ENTRADA DATOS'!$K$4:$K$123,MATCH(LARGE('ENTRADA DATOS'!$L$4:$L$123,17),'ENTRADA DATOS'!$L$4:$L$123,0)),"")
A21: =IF(I21="","",18) | B21: =IFERROR(INDEX('ENTRADA DATOS'!$B$4:$B$123,MATCH(LARGE('ENTRADA DATOS'!$L$4:$L$123,18),'ENTRADA DATOS'!$L$4:$L$123,0)),"") | C21: =IFERROR(INDEX('ENTRADA DATOS'!$C$4:$C$123,MATCH(LARGE('ENTRADA DATOS'!$L$4:$L$123,18),'ENTRADA DATOS'!$L$4:$L$123,0)),"") | D21: =IFERROR(INDEX('ENTRADA DATOS'!$D$4:$D$123,MATCH(LARGE('ENTRADA DATOS'!$L$4:$L$123,18),'ENTRADA DATOS'!$L$4:$L$123,0)),"") | E21: =IFERROR(INDEX('ENTRADA DATOS'!$E$4:$E$123,MATCH(LARGE('ENTRADA DATOS'!$L$4:$L$123,18),'ENTRADA DATOS'!$L$4:$L$123,0)),"") | F21: =IFERROR(INDEX('ENTRADA DATOS'!$F$4:$F$123,MATCH(LARGE('ENTRADA DATOS'!$L$4:$L$123,18),'ENTRADA DATOS'!$L$4:$L$123,0)),"") | G21: =IFERROR(INDEX('ENTRADA DATOS'!$G$4:$G$123,MATCH(LARGE('ENTRADA DATOS'!$L$4:$L$123,18),'ENTRADA DATOS'!$L$4:$L$123,0)),"") | H21: =IFERROR(INDEX('ENTRADA DATOS'!$H$4:$H$123,MATCH(LARGE('ENTRADA DATOS'!$L$4:$L$123,18),'ENTRADA DATOS'!$L$4:$L$123,0)),"") | I21: =IFERROR(INDEX('ENTRADA DATOS'!$I$4:$I$123,MATCH(LARGE('ENTRADA DATOS'!$L$4:$L$123,18),'ENTRADA DATOS'!$L$4:$L$123,0)),"") | J21: =IFERROR(INDEX('ENTRADA DATOS'!$J$4:$J$123,MATCH(LARGE('ENTRADA DATOS'!$L$4:$L$123,18),'ENTRADA DATOS'!$L$4:$L$123,0)),"") | K21: =IFERROR(INDEX('ENTRADA DATOS'!$K$4:$K$123,MATCH(LARGE('ENTRADA DATOS'!$L$4:$L$123,18),'ENTRADA DATOS'!$L$4:$L$123,0)),"")
A22: =IF(I22="","",19) | B22: =IFERROR(INDEX('ENTRADA DATOS'!$B$4:$B$123,MATCH(LARGE('ENTRADA DATOS'!$L$4:$L$123,19),'ENTRADA DATOS'!$L$4:$L$123,0)),"") | C22: =IFERROR(INDEX('ENTRADA DATOS'!$C$4:$C$123,MATCH(LARGE('ENTRADA DATOS'!$L$4:$L$123,19),'ENTRADA DATOS'!$L$4:$L$123,0)),"") | D22: =IFERROR(INDEX('ENTRADA DATOS'!$D$4:$D$123,MATCH(LARGE('ENTRADA DATOS'!$L$4:$L$123,19),'ENTRADA DATOS'!$L$4:$L$123,0)),"") | E22: =IFERROR(INDEX('ENTRADA DATOS'!$E$4:$E$123,MATCH(LARGE('ENTRADA DATOS'!$L$4:$L$123,19),'ENTRADA DATOS'!$L$4:$L$123,0)),"") | F22: =IFERROR(INDEX('ENTRADA DATOS'!$F$4:$F$123,MATCH(LARGE('ENTRADA DATOS'!$L$4:$L$123,19),'ENTRADA DATOS'!$L$4:$L$123,0)),"") | G22: =IFERROR(INDEX('ENTRADA DATOS'!$G$4:$G$123,MATCH(LARGE('ENTRADA DATOS'!$L$4:$L$123,19),'ENTRADA DATOS'!$L$4:$L$123,0)),"") | H22: =IFERROR(INDEX('ENTRADA DATOS'!$H$4:$H$123,MATCH(LARGE('ENTRADA DATOS'!$L$4:$L$123,19),'ENTRADA DATOS'!$L$4:$L$123,0)),"") | I22: =IFERROR(INDEX('ENTRADA DATOS'!$I$4:$I$123,MATCH(LARGE('ENTRADA DATOS'!$L$4:$L$123,19),'ENTRADA DATOS'!$L$4:$L$123,0)),"") | J22: =IFERROR(INDEX('ENTRADA DATOS'!$J$4:$J$123,MATCH(LARGE('ENTRADA DATOS'!$L$4:$L$123,19),'ENTRADA DATOS'!$L$4:$L$123,0)),"") | K22: =IFERROR(INDEX('ENTRADA DATOS'!$K$4:$K$123,MATCH(LARGE('ENTRADA DATOS'!$L$4:$L$123,19),'ENTRADA DATOS'!$L$4:$L$123,0)),"")
A23: =IF(I23="","",20) | B23: =IFERROR(INDEX('ENTRADA DATOS'!$B$4:$B$123,MATCH(LARGE('ENTRADA DATOS'!$L$4:$L$123,20),'ENTRADA DATOS'!$L$4:$L$123,0)),"") | C23: =IFERROR(INDEX('ENTRADA DATOS'!$C$4:$C$123,MATCH(LARGE('ENTRADA DATOS'!$L$4:$L$123,20),'ENTRADA DATOS'!$L$4:$L$123,0)),"") | D23: =IFERROR(INDEX('ENTRADA DATOS'!$D$4:$D$123,MATCH(LARGE('ENTRADA DATOS'!$L$4:$L$123,20),'ENTRADA DATOS'!$L$4:$L$123,0)),"") | E23: =IFERROR(INDEX('ENTRADA DATOS'!$E$4:$E$123,MATCH(LARGE('ENTRADA DATOS'!$L$4:$L$123,20),'ENTRADA DATOS'!$L$4:$L$123,0)),"") | F23: =IFERROR(INDEX('ENTRADA DATOS'!$F$4:$F$123,MATCH(LARGE('ENTRADA DATOS'!$L$4:$L$123,20),'ENTRADA DATOS'!$L$4:$L$123,0)),"") | G23: =IFERROR(INDEX('ENTRADA DATOS'!$G$4:$G$123,MATCH(LARGE('ENTRADA DATOS'!$L$4:$L$123,20),'ENTRADA DATOS'!$L$4:$L$123,0)),"") | H23: =IFERROR(INDEX('ENTRADA DATOS'!$H$4:$H$123,MATCH(LARGE('ENTRADA DATOS'!$L$4:$L$123,20),'ENTRADA DATOS'!$L$4:$L$123,0)),"") | I23: =IFERROR(INDEX('ENTRADA DATOS'!$I$4:$I$123,MATCH(LARGE('ENTRADA DATOS'!$L$4:$L$123,20),'ENTRADA DATOS'!$L$4:$L$123,0)),"") | J23: =IFERROR(INDEX('ENTRADA DATOS'!$J$4:$J$123,MATCH(LARGE('ENTRADA DATOS'!$L$4:$L$123,20),'ENTRADA DATOS'!$L$4:$L$123,0)),"") | K23: =IFERROR(INDEX('ENTRADA DATOS'!$K$4:$K$123,MATCH(LARGE('ENTRADA DATOS'!$L$4:$L$123,20),'ENTRADA DATOS'!$L$4:$L$123,0)),"")
A24: =IF(I24="","",21) | B24: =IFERROR(INDEX('ENTRADA DATOS'!$B$4:$B$123,MATCH(LARGE('ENTRADA DATOS'!$L$4:$L$123,21),'ENTRADA DATOS'!$L$4:$L$123,0)),"") | C24: =IFERROR(INDEX('ENTRADA DATOS'!$C$4:$C$123,MATCH(LARGE('ENTRADA DATOS'!$L$4:$L$123,21),'ENTRADA DATOS'!$L$4:$L$123,0)),"") | D24: =IFERROR(INDEX('ENTRADA DATOS'!$D$4:$D$123,MATCH(LARGE('ENTRADA DATOS'!$L$4:$L$123,21),'ENTRADA DATOS'!$L$4:$L$123,0)),"") | E24: =IFERROR(INDEX('ENTRADA DATOS'!$E$4:$E$123,MATCH(LARGE('ENTRADA DATOS'!$L$4:$L$123,21),'ENTRADA DATOS'!$L$4:$L$123,0)),"") | F24: =IFERROR(INDEX('ENTRADA DATOS'!$F$4:$F$123,MATCH(LARGE('ENTRADA DATOS'!$L$4:$L$123,21),'ENTRADA DATOS'!$L$4:$L$123,0)),"") | G24: =IFERROR(INDEX('ENTRADA DATOS'!$G$4:$G$123,MATCH(LARGE('ENTRADA DATOS'!$L$4:$L$123,21),'ENTRADA DATOS'!$L$4:$L$123,0)),"") | H24: =IFERROR(INDEX('ENTRADA DATOS'!$H$4:$H$123,MATCH(LARGE('ENTRADA DATOS'!$L$4:$L$123,21),'ENTRADA DATOS'!$L$4:$L$123,0)),"") | I24: =IFERROR(INDEX('ENTRADA DATOS'!$I$4:$I$123,MATCH(LARGE('ENTRADA DATOS'!$L$4:$L$123,21),'ENTRADA DATOS'!$L$4:$L$123,0)),"") | J24: =IFERROR(INDEX('ENTRADA DATOS'!$J$4:$J$123,MATCH(LARGE('ENTRADA DATOS'!$L$4:$L$123,21),'ENTRADA DATOS'!$L$4:$L$123,0)),"") | K24: =IFERROR(INDEX('ENTRADA DATOS'!$K$4:$K$123,MATCH(LARGE('ENTRADA DATOS'!$L$4:$L$123,21),'ENTRADA DATOS'!$L$4:$L$123,0)),"")
A25: =IF(I25="","",22) | B25: =IFERROR(INDEX('ENTRADA DATOS'!$B$4:$B$123,MATCH(LARGE('ENTRADA DATOS'!$L$4:$L$123,22),'ENTRADA DATOS'!$L$4:$L$123,0)),"") | C25: =IFERROR(INDEX('ENTRADA DATOS'!$C$4:$C$123,MATCH(LARGE('ENTRADA DATOS'!$L$4:$L$123,22),'ENTRADA DATOS'!$L$4:$L$123,0)),"") | D25: =IFERROR(INDEX('ENTRADA DATOS'!$D$4:$D$123,MATCH(LARGE('ENTRADA DATOS'!$L$4:$L$123,22),'ENTRADA DATOS'!$L$4:$L$123,0)),"") | E25: =IFERROR(INDEX('ENTRADA DATOS'!$E$4:$E$123,MATCH(LARGE('ENTRADA DATOS'!$L$4:$L$123,22),'ENTRADA DATOS'!$L$4:$L$123,0)),"") | F25: =IFERROR(INDEX('ENTRADA DATOS'!$F$4:$F$123,MATCH(LARGE('ENTRADA DATOS'!$L$4:$L$123,22),'ENTRADA DATOS'!$L$4:$L$123,0)),"") | G25: =IFERROR(INDEX('ENTRADA DATOS'!$G$4:$G$123,MATCH(LARGE('ENTRADA DATOS'!$L$4:$L$123,22),'ENTRADA DATOS'!$L$4:$L$123,0)),"") | H25: =IFERROR(INDEX('ENTRADA DATOS'!$H$4:$H$123,MATCH(LARGE('ENTRADA DATOS'!$L$4:$L$123,22),'ENTRADA DATOS'!$L$4:$L$123,0)),"") | I25: =IFERROR(INDEX('ENTRADA DATOS'!$I$4:$I$123,MATCH(LARGE('ENTRADA DATOS'!$L$4:$L$123,22),'ENTRADA DATOS'!$L$4:$L$123,0)),"") | J25: =IFERROR(INDEX('ENTRADA DATOS'!$J$4:$J$123,MATCH(LARGE('ENTRADA DATOS'!$L$4:$L$123,22),'ENTRADA DATOS'!$L$4:$L$123,0)),"") | K25: =IFERROR(INDEX('ENTRADA DATOS'!$K$4:$K$123,MATCH(LARGE('ENTRADA DATOS'!$L$4:$L$123,22),'ENTRADA DATOS'!$L$4:$L$123,0)),"")
A26: =IF(I26="","",23) | B26: =IFERROR(INDEX('ENTRADA DATOS'!$B$4:$B$123,MATCH(LARGE('ENTRADA DATOS'!$L$4:$L$123,23),'ENTRADA DATOS'!$L$4:$L$123,0)),"") | C26: =IFERROR(INDEX('ENTRADA DATOS'!$C$4:$C$123,MATCH(LARGE('ENTRADA DATOS'!$L$4:$L$123,23),'ENTRADA DATOS'!$L$4:$L$123,0)),"") | D26: =IFERROR(INDEX('ENTRADA DATOS'!$D$4:$D$123,MATCH(LARGE('ENTRADA DATOS'!$L$4:$L$123,23),'ENTRADA DATOS'!$L$4:$L$123,0)),"") | E26: =IFERROR(INDEX('ENTRADA DATOS'!$E$4:$E$123,MATCH(LARGE('ENTRADA DATOS'!$L$4:$L$123,23),'ENTRADA DATOS'!$L$4:$L$123,0)),"") | F26: =IFERROR(INDEX('ENTRADA DATOS'!$F$4:$F$123,MATCH(LARGE('ENTRADA DATOS'!$L$4:$L$123,23),'ENTRADA DATOS'!$L$4:$L$123,0)),"") | G26: =IFERROR(INDEX('ENTRADA DATOS'!$G$4:$G$123,MATCH(LARGE('ENTRADA DATOS'!$L$4:$L$123,23),'ENTRADA DATOS'!$L$4:$L$123,0)),"") | H26: =IFERROR(INDEX('ENTRADA DATOS'!$H$4:$H$123,MATCH(LARGE('ENTRADA DATOS'!$L$4:$L$123,23),'ENTRADA DATOS'!$L$4:$L$123,0)),"") | I26: =IFERROR(INDEX('ENTRADA DATOS'!$I$4:$I$123,MATCH(LARGE('ENTRADA DATOS'!$L$4:$L$123,23),'ENTRADA DATOS'!$L$4:$L$123,0)),"") | J26: =IFERROR(INDEX('ENTRADA DATOS'!$J$4:$J$123,MATCH(LARGE('ENTRADA DATOS'!$L$4:$L$123,23),'ENTRADA DATOS'!$L$4:$L$123,0)),"") | K26: =IFERROR(INDEX('ENTRADA DATOS'!$K$4:$K$123,MATCH(LARGE('ENTRADA DATOS'!$L$4:$L$123,23),'ENTRADA DATOS'!$L$4:$L$123,0)),"")
A27: =IF(I27="","",24) | B27: =IFERROR(INDEX('ENTRADA DATOS'!$B$4:$B$123,MATCH(LARGE('ENTRADA DATOS'!$L$4:$L$123,24),'ENTRADA DATOS'!$L$4:$L$123,0)),"") | C27: =IFERROR(INDEX('ENTRADA DATOS'!$C$4:$C$123,MATCH(LARGE('ENTRADA DATOS'!$L$4:$L$123,24),'ENTRADA DATOS'!$L$4:$L$123,0)),"") | D27: =IFERROR(INDEX('ENTRADA DATOS'!$D$4:$D$123,MATCH(LARGE('ENTRADA DATOS'!$L$4:$L$123,24),'ENTRADA DATOS'!$L$4:$L$123,0)),"") | E27: =IFERROR(INDEX('ENTRADA DATOS'!$E$4:$E$123,MATCH(LARGE('ENTRADA DATOS'!$L$4:$L$123,24),'ENTRADA DATOS'!$L$4:$L$123,0)),"") | F27: =IFERROR(INDEX('ENTRADA DATOS'!$F$4:$F$123,MATCH(LARGE('ENTRADA DATOS'!$L$4:$L$123,24),'ENTRADA DATOS'!$L$4:$L$123,0)),"") | G27: =IFERROR(INDEX('ENTRADA DATOS'!$G$4:$G$123,MATCH(LARGE('ENTRADA DATOS'!$L$4:$L$123,24),'ENTRADA DATOS'!$L$4:$L$123,0)),"") | H27: =IFERROR(INDEX('ENTRADA DATOS'!$H$4:$H$123,MATCH(LARGE('ENTRADA DATOS'!$L$4:$L$123,24),'ENTRADA DATOS'!$L$4:$L$123,0)),"") | I27: =IFERROR(INDEX('ENTRADA DATOS'!$I$4:$I$123,MATCH(LARGE('ENTRADA DATOS'!$L$4:$L$123,24),'ENTRADA DATOS'!$L$4:$L$123,0)),"") | J27: =IFERROR(INDEX('ENTRADA DATOS'!$J$4:$J$123,MATCH(LARGE('ENTRADA DATOS'!$L$4:$L$123,24),'ENTRADA DATOS'!$L$4:$L$123,0)),"") | K27: =IFERROR(INDEX('ENTRADA DATOS'!$K$4:$K$123,MATCH(LARGE('ENTRADA DATOS'!$L$4:$L$123,24),'ENTRADA DATOS'!$L$4:$L$123,0)),"")
A28: =IF(I28="","",25) | B28: =IFERROR(INDEX('ENTRADA DATOS'!$B$4:$B$123,MATCH(LARGE('ENTRADA DATOS'!$L$4:$L$123,25),'ENTRADA DATOS'!$L$4:$L$123,0)),"") | C28: =IFERROR(INDEX('ENTRADA DATOS'!$C$4:$C$123,MATCH(LARGE('ENTRADA DATOS'!$L$4:$L$123,25),'ENTRADA DATOS'!$L$4:$L$123,0)),"") | D28: =IFERROR(INDEX('ENTRADA DATOS'!$D$4:$D$123,MATCH(LARGE('ENTRADA DATOS'!$L$4:$L$123,25),'ENTRADA DATOS'!$L$4:$L$123,0)),"") | E28: =IFERROR(INDEX('ENTRADA DATOS'!$E$4:$E$123,MATCH(LARGE('ENTRADA DATOS'!$L$4:$L$123,25),'ENTRADA DATOS'!$L$4:$L$123,0)),"") | F28: =IFERROR(INDEX('ENTRADA DATOS'!$F$4:$F$123,MATCH(LARGE('ENTRADA DATOS'!$L$4:$L$123,25),'ENTRADA DATOS'!$L$4:$L$123,0)),"") | G28: =IFERROR(INDEX('ENTRADA DATOS'!$G$4:$G$123,MATCH(LARGE('ENTRADA DATOS'!$L$4:$L$123,25),'ENTRADA DATOS'!$L$4:$L$123,0)),"") | H28: =IFERROR(INDEX('ENTRADA DATOS'!$H$4:$H$123,MATCH(LARGE('ENTRADA DATOS'!$L$4:$L$123,25),'ENTRADA DATOS'!$L$4:$L$123,0)),"") | I28: =IFERROR(INDEX('ENTRADA DATOS'!$I$4:$I$123,MATCH(LARGE('ENTRADA DATOS'!$L$4:$L$123,25),'ENTRADA DATOS'!$L$4:$L$123,0)),"") | J28: =IFERROR(INDEX('ENTRADA DATOS'!$J$4:$J$123,MATCH(LARGE('ENTRADA DATOS'!$L$4:$L$123,25),'ENTRADA DATOS'!$L$4:$L$123,0)),"") | K28: =IFERROR(INDEX('ENTRADA DATOS'!$K$4:$K$123,MATCH(LARGE('ENTRADA DATOS'!$L$4:$L$123,25),'ENTRADA DATOS'!$L$4:$L$123,0)),"")
A29: =IF(I29="","",26) | B29: =IFERROR(INDEX('ENTRADA DATOS'!$B$4:$B$123,MATCH(LARGE('ENTRADA DATOS'!$L$4:$L$123,26),'ENTRADA DATOS'!$L$4:$L$123,0)),"") | C29: =IFERROR(INDEX('ENTRADA DATOS'!$C$4:$C$123,MATCH(LARGE('ENTRADA DATOS'!$L$4:$L$123,26),'ENTRADA DATOS'!$L$4:$L$123,0)),"") | D29: =IFERROR(INDEX('ENTRADA DATOS'!$D$4:$D$123,MATCH(LARGE('ENTRADA DATOS'!$L$4:$L$123,26),'ENTRADA DATOS'!$L$4:$L$123,0)),"") | E29: =IFERROR(INDEX('ENTRADA DATOS'!$E$4:$E$123,MATCH(LARGE('ENTRADA DATOS'!$L$4:$L$123,26),'ENTRADA DATOS'!$L$4:$L$123,0)),"") | F29: =IFERROR(INDEX('ENTRADA DATOS'!$F$4:$F$123,MATCH(LARGE('ENTRADA DATOS'!$L$4:$L$123,26),'ENTRADA DATOS'!$L$4:$L$123,0)),"") | G29: =IFERROR(INDEX('ENTRADA DATOS'!$G$4:$G$123,MATCH(LARGE('ENTRADA DATOS'!$L$4:$L$123,26),'ENTRADA DATOS'!$L$4:$L$123,0)),"") | H29: =IFERROR(INDEX('ENTRADA DATOS'!$H$4:$H$123,MATCH(LARGE('ENTRADA DATOS'!$L$4:$L$123,26),'ENTRADA DATOS'!$L$4:$L$123,0)),"") | I29: =IFERROR(INDEX('ENTRADA DATOS'!$I$4:$I$123,MATCH(LARGE('ENTRADA DATOS'!$L$4:$L$123,26),'ENTRADA DATOS'!$L$4:$L$123,0)),"") | J29: =IFERROR(INDEX('ENTRADA DATOS'!$J$4:$J$123,MATCH(LARGE('ENTRADA DATOS'!$L$4:$L$123,26),'ENTRADA DATOS'!$L$4:$L$123,0)),"") | K29: =IFERROR(INDEX('ENTRADA DATOS'!$K$4:$K$123,MATCH(LARGE('ENTRADA DATOS'!$L$4:$L$123,26),'ENTRADA DATOS'!$L$4:$L$123,0)),"")
A30: =IF(I30="","",27) | B30: =IFERROR(INDEX('ENTRADA DATOS'!$B$4:$B$123,MATCH(LARGE('ENTRADA DATOS'!$L$4:$L$123,27),'ENTRADA DATOS'!$L$4:$L$123,0)),"") | C30: =IFERROR(INDEX('ENTRADA DATOS'!$C$4:$C$123,MATCH(LARGE('ENTRADA DATOS'!$L$4:$L$123,27),'ENTRADA DATOS'!$L$4:$L$123,0)),"") | D30: =IFERROR(INDEX('ENTRADA DATOS'!$D$4:$D$123,MATCH(LARGE('ENTRADA DATOS'!$L$4:$L$123,27),'ENTRADA DATOS'!$L$4:$L$123,0)),"") | E30: =IFERROR(INDEX('ENTRADA DATOS'!$E$4:$E$123,MATCH(LARGE('ENTRADA DATOS'!$L$4:$L$123,27),'ENTRADA DATOS'!$L$4:$L$123,0)),"") | F30: =IFERROR(INDEX('ENTRADA DATOS'!$F$4:$F$123,MATCH(LARGE('ENTRADA DATOS'!$L$4:$L$123,27),'ENTRADA DATOS'!$L$4:$L$123,0)),"") | G30: =IFERROR(INDEX('ENTRADA DATOS'!$G$4:$G$123,MATCH(LARGE('ENTRADA DATOS'!$L$4:$L$123,27),'ENTRADA DATOS'!$L$4:$L$123,0)),"") | H30: =IFERROR(INDEX('ENTRADA DATOS'!$H$4:$H$123,MATCH(LARGE('ENTRADA DATOS'!$L$4:$L$123,27),'ENTRADA DATOS'!$L$4:$L$123,0)),"") | I30: =IFERROR(INDEX('ENTRADA DATOS'!$I$4:$I$123,MATCH(LARGE('ENTRADA DATOS'!$L$4:$L$123,27),'ENTRADA DATOS'!$L$4:$L$123,0)),"") | J30: =IFERROR(INDEX('ENTRADA DATOS'!$J$4:$J$123,MATCH(LARGE('ENTRADA DATOS'!$L$4:$L$123,27),'ENTRADA DATOS'!$L$4:$L$123,0)),"") | K30: =IFERROR(INDEX('ENTRADA DATOS'!$K$4:$K$123,MATCH(LARGE('ENTRADA DATOS'!$L$4:$L$123,27),'ENTRADA DATOS'!$L$4:$L$123,0)),"")
A31: =IF(I31="","",28) | B31: =IFERROR(INDEX('ENTRADA DATOS'!$B$4:$B$123,MATCH(LARGE('ENTRADA DATOS'!$L$4:$L$123,28),'ENTRADA DATOS'!$L$4:$L$123,0)),"") | C31: =IFERROR(INDEX('ENTRADA DATOS'!$C$4:$C$123,MATCH(LARGE('ENTRADA DATOS'!$L$4:$L$123,28),'ENTRADA DATOS'!$L$4:$L$123,0)),"") | D31: =IFERROR(INDEX('ENTRADA DATOS'!$D$4:$D$123,MATCH(LARGE('ENTRADA DATOS'!$L$4:$L$123,28),'ENTRADA DATOS'!$L$4:$L$123,0)),"") | E31: =IFERROR(INDEX('ENTRADA DATOS'!$E$4:$E$123,MATCH(LARGE('ENTRADA DATOS'!$L$4:$L$123,28),'ENTRADA DATOS'!$L$4:$L$123,0)),"") | F31: =IFERROR(INDEX('ENTRADA DATOS'!$F$4:$F$123,MATCH(LARGE('ENTRADA DATOS'!$L$4:$L$123,28),'ENTRADA DATOS'!$L$4:$L$123,0)),"") | G31: =IFERROR(INDEX('ENTRADA DATOS'!$G$4:$G$123,MATCH(LARGE('ENTRADA DATOS'!$L$4:$L$123,28),'ENTRADA DATOS'!$L$4:$L$123,0)),"") | H31: =IFERROR(INDEX('ENTRADA DATOS'!$H$4:$H$123,MATCH(LARGE('ENTRADA DATOS'!$L$4:$L$123,28),'ENTRADA DATOS'!$L$4:$L$123,0)),"") | I31: =IFERROR(INDEX('ENTRADA DATOS'!$I$4:$I$123,MATCH(LARGE('ENTRADA DATOS'!$L$4:$L$123,28),'ENTRADA DATOS'!$L$4:$L$123,0)),"") | J31: =IFERROR(INDEX('ENTRADA DATOS'!$J$4:$J$123,MATCH(LARGE('ENTRADA DATOS'!$L$4:$L$123,28),'ENTRADA DATOS'!$L$4:$L$123,0)),"") | K31: =IFERROR(INDEX('ENTRADA DATOS'!$K$4:$K$123,MATCH(LARGE('ENTRADA DATOS'!$L$4:$L$123,28),'ENTRADA DATOS'!$L$4:$L$123,0)),"")
A32: =IF(I32="","",29) | B32: =IFERROR(INDEX('ENTRADA DATOS'!$B$4:$B$123,MATCH(LARGE('ENTRADA DATOS'!$L$4:$L$123,29),'ENTRADA DATOS'!$L$4:$L$123,0)),"") | C32: =IFERROR(INDEX('ENTRADA DATOS'!$C$4:$C$123,MATCH(LARGE('ENTRADA DATOS'!$L$4:$L$123,29),'ENTRADA DATOS'!$L$4:$L$123,0)),"") | D32: =IFERROR(INDEX('ENTRADA DATOS'!$D$4:$D$123,MATCH(LARGE('ENTRADA DATOS'!$L$4:$L$123,29),'ENTRADA DATOS'!$L$4:$L$123,0)),"") | E32: =IFERROR(INDEX('ENTRADA DATOS'!$E$4:$E$123,MATCH(LARGE('ENTRADA DATOS'!$L$4:$L$123,29),'ENTRADA DATOS'!$L$4:$L$123,0)),"") | F32: =IFERROR(INDEX('ENTRADA DATOS'!$F$4:$F$123,MATCH(LARGE('ENTRADA DATOS'!$L$4:$L$123,29),'ENTRADA DATOS'!$L$4:$L$123,0)),"") | G32: =IFERROR(INDEX('ENTRADA DATOS'!$G$4:$G$123,MATCH(LARGE('ENTRADA DATOS'!$L$4:$L$123,29),'ENTRADA DATOS'!$L$4:$L$123,0)),"") | H32: =IFERROR(INDEX('ENTRADA DATOS'!$H$4:$H$123,MATCH(LARGE('ENTRADA DATOS'!$L$4:$L$123,29),'ENTRADA DATOS'!$L$4:$L$123,0)),"") | I32: =IFERROR(INDEX('ENTRADA DATOS'!$I$4:$I$123,MATCH(LARGE('ENTRADA DATOS'!$L$4:$L$123,29),'ENTRADA DATOS'!$L$4:$L$123,0)),"") | J32: =IFERROR(INDEX('ENTRADA DATOS'!$J$4:$J$123,MATCH(LARGE('ENTRADA DATOS'!$L$4:$L$123,29),'ENTRADA DATOS'!$L$4:$L$123,0)),"") | K32: =IFERROR(INDEX('ENTRADA DATOS'!$K$4:$K$123,MATCH(LARGE('ENTRADA DATOS'!$L$4:$L$123,29),'ENTRADA DATOS'!$L$4:$L$123,0)),"")
A33: =IF(I33="","",30) | B33: =IFERROR(INDEX('ENTRADA DATOS'!$B$4:$B$123,MATCH(LARGE('ENTRADA DATOS'!$L$4:$L$123,30),'ENTRADA DATOS'!$L$4:$L$123,0)),"") | C33: =IFERROR(INDEX('ENTRADA DATOS'!$C$4:$C$123,MATCH(LARGE('ENTRADA DATOS'!$L$4:$L$123,30),'ENTRADA DATOS'!$L$4:$L$123,0)),"") | D33: =IFERROR(INDEX('ENTRADA DATOS'!$D$4:$D$123,MATCH(LARGE('ENTRADA DATOS'!$L$4:$L$123,30),'ENTRADA DATOS'!$L$4:$L$123,0)),"") | E33: =IFERROR(INDEX('ENTRADA DATOS'!$E$4:$E$123,MATCH(LARGE('ENTRADA DATOS'!$L$4:$L$123,30),'ENTRADA DATOS'!$L$4:$L$123,0)),"") | F33: =IFERROR(INDEX('ENTRADA DATOS'!$F$4:$F$123,MATCH(LARGE('ENTRADA DATOS'!$L$4:$L$123,30),'ENTRADA DATOS'!$L$4:$L$123,0)),"") | G33: =IFERROR(INDEX('ENTRADA DATOS'!$G$4:$G$123,MATCH(LARGE('ENTRADA DATOS'!$L$4:$L$123,30),'ENTRADA DATOS'!$L$4:$L$123,0)),"") | H33: =IFERROR(INDEX('ENTRADA DATOS'!$H$4:$H$123,MATCH(LARGE('ENTRADA DATOS'!$L$4:$L$123,30),'ENTRADA DATOS'!$L$4:$L$123,0)),"") | I33: =IFERROR(INDEX('ENTRADA DATOS'!$I$4:$I$123,MATCH(LARGE('ENTRADA DATOS'!$L$4:$L$123,30),'ENTRADA DATOS'!$L$4:$L$123,0)),"") | J33: =IFERROR(INDEX('ENTRADA DATOS'!$J$4:$J$123,MATCH(LARGE('ENTRADA DATOS'!$L$4:$L$123,30),'ENTRADA DATOS'!$L$4:$L$123,0)),"") | K33: =IFERROR(INDEX('ENTRADA DATOS'!$K$4:$K$123,MATCH(LARGE('ENTRADA DATOS'!$L$4:$L$123,30),'ENTRADA DATOS'!$L$4:$L$123,0)),"")
A34: =IF(I34="","",31) | B34: =IFERROR(INDEX('ENTRADA DATOS'!$B$4:$B$123,MATCH(LARGE('ENTRADA DATOS'!$L$4:$L$123,31),'ENTRADA DATOS'!$L$4:$L$123,0)),"") | C34: =IFERROR(INDEX('ENTRADA DATOS'!$C$4:$C$123,MATCH(LARGE('ENTRADA DATOS'!$L$4:$L$123,31),'ENTRADA DATOS'!$L$4:$L$123,0)),"") | D34: =IFERROR(INDEX('ENTRADA DATOS'!$D$4:$D$123,MATCH(LARGE('ENTRADA DATOS'!$L$4:$L$123,31),'ENTRADA DATOS'!$L$4:$L$123,0)),"") | E34: =IFERROR(INDEX('ENTRADA DATOS'!$E$4:$E$123,MATCH(LARGE('ENTRADA DATOS'!$L$4:$L$123,31),'ENTRADA DATOS'!$L$4:$L$123,0)),"") | F34: =IFERROR(INDEX('ENTRADA DATOS'!$F$4:$F$123,MATCH(LARGE('ENTRADA DATOS'!$L$4:$L$123,31),'ENTRADA DATOS'!$L$4:$L$123,0)),"") | G34: =IFERROR(INDEX('ENTRADA DATOS'!$G$4:$G$123,MATCH(LARGE('ENTRADA DATOS'!$L$4:$L$123,31),'ENTRADA DATOS'!$L$4:$L$123,0)),"") | H34: =IFERROR(INDEX('ENTRADA DATOS'!$H$4:$H$123,MATCH(LARGE('ENTRADA DATOS'!$L$4:$L$123,31),'ENTRADA DATOS'!$L$4:$L$123,0)),"") | I34: =IFERROR(INDEX('ENTRADA DATOS'!$I$4:$I$123,MATCH(LARGE('ENTRADA DATOS'!$L$4:$L$123,31),'ENTRADA DATOS'!$L$4:$L$123,0)),"") | J34: =IFERROR(INDEX('ENTRADA DATOS'!$J$4:$J$123,MATCH(LARGE('ENTRADA DATOS'!$L$4:$L$123,31),'ENTRADA DATOS'!$L$4:$L$123,0)),"") | K34: =IFERROR(INDEX('ENTRADA DATOS'!$K$4:$K$123,MATCH(LARGE('ENTRADA DATOS'!$L$4:$L$123,31),'ENTRADA DATOS'!$L$4:$L$123,0)),"")
A35: =IF(I35="","",32) | B35: =IFERROR(INDEX('ENTRADA DATOS'!$B$4:$B$123,MATCH(LARGE('ENTRADA DATOS'!$L$4:$L$123,32),'ENTRADA DATOS'!$L$4:$L$123,0)),"") | C35: =IFERROR(INDEX('ENTRADA DATOS'!$C$4:$C$123,MATCH(LARGE('ENTRADA DATOS'!$L$4:$L$123,32),'ENTRADA DATOS'!$L$4:$L$123,0)),"") | D35: =IFERROR(INDEX('ENTRADA DATOS'!$D$4:$D$123,MATCH(LARGE('ENTRADA DATOS'!$L$4:$L$123,32),'ENTRADA DATOS'!$L$4:$L$123,0)),"") | E35: =IFERROR(INDEX('ENTRADA DATOS'!$E$4:$E$123,MATCH(LARGE('ENTRADA DATOS'!$L$4:$L$123,32),'ENTRADA DATOS'!$L$4:$L$123,0)),"") | F35: =IFERROR(INDEX('ENTRADA DATOS'!$F$4:$F$123,MATCH(LARGE('ENTRADA DATOS'!$L$4:$L$123,32),'ENTRADA DATOS'!$L$4:$L$123,0)),"") | G35: =IFERROR(INDEX('ENTRADA DATOS'!$G$4:$G$123,MATCH(LARGE('ENTRADA DATOS'!$L$4:$L$123,32),'ENTRADA DATOS'!$L$4:$L$123,0)),"") | H35: =IFERROR(INDEX('ENTRADA DATOS'!$H$4:$H$123,MATCH(LARGE('ENTRADA DATOS'!$L$4:$L$123,32),'ENTRADA DATOS'!$L$4:$L$123,0)),"") | I35: =IFERROR(INDEX('ENTRADA DATOS'!$I$4:$I$123,MATCH(LARGE('ENTRADA DATOS'!$L$4:$L$123,32),'ENTRADA DATOS'!$L$4:$L$123,0)),"") | J35: =IFERROR(INDEX('ENTRADA DATOS'!$J$4:$J$123,MATCH(LARGE('ENTRADA DATOS'!$L$4:$L$123,32),'ENTRADA DATOS'!$L$4:$L$123,0)),"") | K35: =IFERROR(INDEX('ENTRADA DATOS'!$K$4:$K$123,MATCH(LARGE('ENTRADA DATOS'!$L$4:$L$123,32),'ENTRADA DATOS'!$L$4:$L$123,0)),"")
A36: =IF(I36="","",33) | B36: =IFERROR(INDEX('ENTRADA DATOS'!$B$4:$B$123,MATCH(LARGE('ENTRADA DATOS'!$L$4:$L$123,33),'ENTRADA DATOS'!$L$4:$L$123,0)),"") | C36: =IFERROR(INDEX('ENTRADA DATOS'!$C$4:$C$123,MATCH(LARGE('ENTRADA DATOS'!$L$4:$L$123,33),'ENTRADA DATOS'!$L$4:$L$123,0)),"") | D36: =IFERROR(INDEX('ENTRADA DATOS'!$D$4:$D$123,MATCH(LARGE('ENTRADA DATOS'!$L$4:$L$123,33),'ENTRADA DATOS'!$L$4:$L$123,0)),"") | E36: =IFERROR(INDEX('ENTRADA DATOS'!$E$4:$E$123,MATCH(LARGE('ENTRADA DATOS'!$L$4:$L$123,33),'ENTRADA DATOS'!$L$4:$L$123,0)),"") | F36: =IFERROR(INDEX('ENTRADA DATOS'!$F$4:$F$123,MATCH(LARGE('ENTRADA DATOS'!$L$4:$L$123,33),'ENTRADA DATOS'!$L$4:$L$123,0)),"") | G36: =IFERROR(INDEX('ENTRADA DATOS'!$G$4:$G$123,MATCH(LARGE('ENTRADA DATOS'!$L$4:$L$123,33),'ENTRADA DATOS'!$L$4:$L$123,0)),"") | H36: =IFERROR(INDEX('ENTRADA DATOS'!$H$4:$H$123,MATCH(LARGE('ENTRADA DATOS'!$L$4:$L$123,33),'ENTRADA DATOS'!$L$4:$L$123,0)),"") | I36: =IFERROR(INDEX('ENTRADA DATOS'!$I$4:$I$123,MATCH(LARGE('ENTRADA DATOS'!$L$4:$L$123,33),'ENTRADA DATOS'!$L$4:$L$123,0)),"") | J36: =IFERROR(INDEX('ENTRADA DATOS'!$J$4:$J$123,MATCH(LARGE('ENTRADA DATOS'!$L$4:$L$123,33),'ENTRADA DATOS'!$L$4:$L$123,0)),"") | K36: =IFERROR(INDEX('ENTRADA DATOS'!$K$4:$K$123,MATCH(LARGE('ENTRADA DATOS'!$L$4:$L$123,33),'ENTRADA DATOS'!$L$4:$L$123,0)),"")
A37: =IF(I37="","",34) | B37: =IFERROR(INDEX('ENTRADA DATOS'!$B$4:$B$123,MATCH(LARGE('ENTRADA DATOS'!$L$4:$L$123,34),'ENTRADA DATOS'!$L$4:$L$123,0)),"") | C37: =IFERROR(INDEX('ENTRADA DATOS'!$C$4:$C$123,MATCH(LARGE('ENTRADA DATOS'!$L$4:$L$123,34),'ENTRADA DATOS'!$L$4:$L$123,0)),"") | D37: =IFERROR(INDEX('ENTRADA DATOS'!$D$4:$D$123,MATCH(LARGE('ENTRADA DATOS'!$L$4:$L$123,34),'ENTRADA DATOS'!$L$4:$L$123,0)),"") | E37: =IFERROR(INDEX('ENTRADA DATOS'!$E$4:$E$123,MATCH(LARGE('ENTRADA DATOS'!$L$4:$L$123,34),'ENTRADA DATOS'!$L$4:$L$123,0)),"") | F37: =IFERROR(INDEX('ENTRADA DATOS'!$F$4:$F$123,MATCH(LARGE('ENTRADA DATOS'!$L$4:$L$123,34),'ENTRADA DATOS'!$L$4:$L$123,0)),"") | G37: =IFERROR(INDEX('ENTRADA DATOS'!$G$4:$G$123,MATCH(LARGE('ENTRADA DATOS'!$L$4:$L$123,34),'ENTRADA DATOS'!$L$4:$L$123,0)),"") | H37: =IFERROR(INDEX('ENTRADA DATOS'!$H$4:$H$123,MATCH(LARGE('ENTRADA DATOS'!$L$4:$L$123,34),'ENTRADA DATOS'!$L$4:$L$123,0)),"") | I37: =IFERROR(INDEX('ENTRADA DATOS'!$I$4:$I$123,MATCH(LARGE('ENTRADA DATOS'!$L$4:$L$123,34),'ENTRADA DATOS'!$L$4:$L$123,0)),"") | J37: =IFERROR(INDEX('ENTRADA DATOS'!$J$4:$J$123,MATCH(LARGE('ENTRADA DATOS'!$L$4:$L$123,34),'ENTRADA DATOS'!$L$4:$L$123,0)),"") | K37: =IFERROR(INDEX('ENTRADA DATOS'!$K$4:$K$123,MATCH(LARGE('ENTRADA DATOS'!$L$4:$L$123,34),'ENTRADA DATOS'!$L$4:$L$123,0)),"")
A38: =IF(I38="","",35) | B38: =IFERROR(INDEX('ENTRADA DATOS'!$B$4:$B$123,MATCH(LARGE('ENTRADA DATOS'!$L$4:$L$123,35),'ENTRADA DATOS'!$L$4:$L$123,0)),"") | C38: =IFERROR(INDEX('ENTRADA DATOS'!$C$4:$C$123,MATCH(LARGE('ENTRADA DATOS'!$L$4:$L$123,35),'ENTRADA DATOS'!$L$4:$L$123,0)),"") | D38: =IFERROR(INDEX('ENTRADA DATOS'!$D$4:$D$123,MATCH(LARGE('ENTRADA DATOS'!$L$4:$L$123,35),'ENTRADA DATOS'!$L$4:$L$123,0)),"") | E38: =IFERROR(INDEX('ENTRADA DATOS'!$E$4:$E$123,MATCH(LARGE('ENTRADA DATOS'!$L$4:$L$123,35),'ENTRADA DATOS'!$L$4:$L$123,0)),"") | F38: =IFERROR(INDEX('ENTRADA DATOS'!$F$4:$F$123,MATCH(LARGE('ENTRADA DATOS'!$L$4:$L$123,35),'ENTRADA DATOS'!$L$4:$L$123,0)),"") | G38: =IFERROR(INDEX('ENTRADA DATOS'!$G$4:$G$123,MATCH(LARGE('ENTRADA DATOS'!$L$4:$L$123,35),'ENTRADA DATOS'!$L$4:$L$123,0)),"") | H38: =IFERROR(INDEX('ENTRADA DATOS'!$H$4:$H$123,MATCH(LARGE('ENTRADA DATOS'!$L$4:$L$123,35),'ENTRADA DATOS'!$L$4:$L$123,0)),"") | I38: =IFERROR(INDEX('ENTRADA DATOS'!$I$4:$I$123,MATCH(LARGE('ENTRADA DATOS'!$L$4:$L$123,35),'ENTRADA DATOS'!$L$4:$L$123,0)),"") | J38: =IFERROR(INDEX('ENTRADA DATOS'!$J$4:$J$123,MATCH(LARGE('ENTRADA DATOS'!$L$4:$L$123,35),'ENTRADA DATOS'!$L$4:$L$123,0)),"") | K38: =IFERROR(INDEX('ENTRADA DATOS'!$K$4:$K$123,MATCH(LARGE('ENTRADA DATOS'!$L$4:$L$123,35),'ENTRADA DATOS'!$L$4:$L$123,0)),"")
A39: =IF(I39="","",36) | B39: =IFERROR(INDEX('ENTRADA DATOS'!$B$4:$B$123,MATCH(LARGE('ENTRADA DATOS'!$L$4:$L$123,36),'ENTRADA DATOS'!$L$4:$L$123,0)),"") | C39: =IFERROR(INDEX('ENTRADA DATOS'!$C$4:$C$123,MATCH(LARGE('ENTRADA DATOS'!$L$4:$L$123,36),'ENTRADA DATOS'!$L$4:$L$123,0)),"") | D39: =IFERROR(INDEX('ENTRADA DATOS'!$D$4:$D$123,MATCH(LARGE('ENTRADA DATOS'!$L$4:$L$123,36),'ENTRADA DATOS'!$L$4:$L$123,0)),"") | E39: =IFERROR(INDEX('ENTRADA DATOS'!$E$4:$E$123,MATCH(LARGE('ENTRADA DATOS'!$L$4:$L$123,36),'ENTRADA DATOS'!$L$4:$L$123,0)),"") | F39: =IFERROR(INDEX('ENTRADA DATOS'!$F$4:$F$123,MATCH(LARGE('ENTRADA DATOS'!$L$4:$L$123,36),'ENTRADA DATOS'!$L$4:$L$123,0)),"") | G39: =IFERROR(INDEX('ENTRADA DATOS'!$G$4:$G$123,MATCH(LARGE('ENTRADA DATOS'!$L$4:$L$123,36),'ENTRADA DATOS'!$L$4:$L$123,0)),"") | H39: =IFERROR(INDEX('ENTRADA DATOS'!$H$4:$H$123,MATCH(LARGE('ENTRADA DATOS'!$L$4:$L$123,36),'ENTRADA DATOS'!$L$4:$L$123,0)),"") | I39: =IFERROR(INDEX('ENTRADA DATOS'!$I$4:$I$123,MATCH(LARGE('ENTRADA DATOS'!$L$4:$L$123,36),'ENTRADA DATOS'!$L$4:$L$123,0)),"") | J39: =IFERROR(INDEX('ENTRADA DATOS'!$J$4:$J$123,MATCH(LARGE('ENTRADA DATOS'!$L$4:$L$123,36),'ENTRADA DATOS'!$L$4:$L$123,0)),"") | K39: =IFERROR(INDEX('ENTRADA DATOS'!$K$4:$K$123,MATCH(LARGE('ENTRADA DATOS'!$L$4:$L$123,36),'ENTRADA DATOS'!$L$4:$L$123,0)),"")
A40: =IF(I40="","",37) | B40: =IFERROR(INDEX('ENTRADA DATOS'!$B$4:$B$123,MATCH(LARGE('ENTRADA DATOS'!$L$4:$L$123,37),'ENTRADA DATOS'!$L$4:$L$123,0)),"") | C40: =IFERROR(INDEX('ENTRADA DATOS'!$C$4:$C$123,MATCH(LARGE('ENTRADA DATOS'!$L$4:$L$123,37),'ENTRADA DATOS'!$L$4:$L$123,0)),"") | D40: =IFERROR(INDEX('ENTRADA DATOS'!$D$4:$D$123,MATCH(LARGE('ENTRADA DATOS'!$L$4:$L$123,37),'ENTRADA DATOS'!$L$4:$L$123,0)),"") | E40: =IFERROR(INDEX('ENTRADA DATOS'!$E$4:$E$123,MATCH(LARGE('ENTRADA DATOS'!$L$4:$L$123,37),'ENTRADA DATOS'!$L$4:$L$123,0)),"") | F40: =IFERROR(INDEX('ENTRADA DATOS'!$F$4:$F$123,MATCH(LARGE('ENTRADA DATOS'!$L$4:$L$123,37),'ENTRADA DATOS'!$L$4:$L$123,0)),"") | G40: =IFERROR(INDEX('ENTRADA DATOS'!$G$4:$G$123,MATCH(LARGE('ENTRADA DATOS'!$L$4:$L$123,37),'ENTRADA DATOS'!$L$4:$L$123,0)),"") | H40: =IFERROR(INDEX('ENTRADA DATOS'!$H$4:$H$123,MATCH(LARGE('ENTRADA DATOS'!$L$4:$L$123,37),'ENTRADA DATOS'!$L$4:$L$123,0)),"") | I40: =IFERROR(INDEX('ENTRADA DATOS'!$I$4:$I$123,MATCH(LARGE('ENTRADA DATOS'!$L$4:$L$123,37),'ENTRADA DATOS'!$L$4:$L$123,0)),"") | J40: =IFERROR(INDEX('ENTRADA DATOS'!$J$4:$J$123,MATCH(LARGE('ENTRADA DATOS'!$L$4:$L$123,37),'ENTRADA DATOS'!$L$4:$L$123,0)),"") | K40: =IFERROR(INDEX('ENTRADA DATOS'!$K$4:$K$123,MATCH(LARGE('ENTRADA DATOS'!$L$4:$L$123,37),'ENTRADA DATOS'!$L$4:$L$123,0)),"")
...
